C:\Users\pante\Desktop\An3_sem1\PF\Proiect_Elm\elm-stuff\generated-code\elm-community\elm-test\0.19.1-revision12\elmTestOutput.js:559
			throw new Error('TODO in module `' + moduleName + '` ' + _Debug_regionToString(region) + '\n\n' + message);
			^

Error: TODO in module `Model.Post` on line 38

Post.decode
    at _Debug_crash (C:\Users\pante\Desktop\An3_sem1\PF\Proiect_Elm\elm-stuff\generated-code\elm-community\elm-test\0.19.1-revision12\elmTestOutput.js:559:10)
    at C:\Users\pante\Desktop\An3_sem1\PF\Proiect_Elm\elm-stuff\generated-code\elm-community\elm-test\0.19.1-revision12\elmTestOutput.js:315:3
    at C:\Users\pante\Desktop\An3_sem1\PF\Proiect_Elm\elm-stuff\generated-code\elm-community\elm-test\0.19.1-revision12\elmTestOutput.js:9238:4
    at C:\Users\pante\Desktop\An3_sem1\PF\Proiect_Elm\elm-stuff\generated-code\elm-community\elm-test\0.19.1-revision12\elmTestOutput.js:25581:132
    at Object.<anonymous> (C:\Users\pante\Desktop\An3_sem1\PF\Proiect_Elm\elm-stuff\generated-code\elm-community\elm-test\0.19.1-revision12\elmTestOutput.js:25583:3)
    at Module._compile (node:internal/modules/cjs/loader:1469:14)
    at Module._extensions..js (node:internal/modules/cjs/loader:1548:10)
    at Module.load (node:internal/modules/cjs/loader:1288:32)
    at Module._load (node:internal/modules/cjs/loader:1104:12)
    at Function.executeUserEntryPoint [as runMain] (node:internal/modules/run_main:174:12)

Node.js v20.18.0
C:\Users\pante\Desktop\An3_sem1\PF\Proiect_Elm\elm-stuff\generated-code\elm-community\elm-test\0.19.1-revision12\elmTestOutput.js:559
			throw new Error('TODO in module `' + moduleName + '` ' + _Debug_regionToString(region) + '\n\n' + message);
			^

Error: TODO in module `Model.Post` on line 38

Post.decode
    at _Debug_crash (C:\Users\pante\Desktop\An3_sem1\PF\Proiect_Elm\elm-stuff\generated-code\elm-community\elm-test\0.19.1-revision12\elmTestOutput.js:559:10)
    at C:\Users\pante\Desktop\An3_sem1\PF\Proiect_Elm\elm-stuff\generated-code\elm-community\elm-test\0.19.1-revision12\elmTestOutput.js:315:3
    at C:\Users\pante\Desktop\An3_sem1\PF\Proiect_Elm\elm-stuff\generated-code\elm-community\elm-test\0.19.1-revision12\elmTestOutput.js:9238:4
    at C:\Users\pante\Desktop\An3_sem1\PF\Proiect_Elm\elm-stuff\generated-code\elm-community\elm-test\0.19.1-revision12\elmTestOutput.js:25581:132
    at Object.<anonymous> (C:\Users\pante\Desktop\An3_sem1\PF\Proiect_Elm\elm-stuff\generated-code\elm-community\elm-test\0.19.1-revision12\elmTestOutput.js:25583:3)
    at Module._compile (node:internal/modules/cjs/loader:1469:14)
    at Module._extensions..js (node:internal/modules/cjs/loader:1548:10)
    at Module.load (node:internal/modules/cjs/loader:1288:32)
    at Module._load (node:internal/modules/cjs/loader:1104:12)
    at Function.executeUserEntryPoint [as runMain] (node:internal/modules/run_main:174:12)

Node.js v20.18.0


There was an unexpected runtime exception while running tests


